Workbook

Sheet contrib PPTO
A1: Sucursal | B1: 45658 | C1: 45689 | D1: 45717 | E1: 45748 | F1: 45778 | G1: 45809 | H1: 45839 | I1: 45870 | J1: 45901 | K1: 45931 | L1: 45962 | M1: 45992 | N1: 46023 | O1: 46054 | P1: 46082 | Q1: 46113 | R1: 46143 | S1: 46174 | T1: 46204 | U1: 46235 | V1: 46266 | W1: 46296 | X1: 46327 | Y1: 46357 | AA1: Banner
A2: 1000-Belsport Ahumada | B2: 40708.648 | C2: 76391.457 | D2: 82480.455 | E2: 57960.932 | F2: 55346.08 | G2: 56756.371 | H2: 54153.583 | I2: 73398.187 | J2: 83417.009 | K2: 67291.104 | L2: 71934.422 | M2: 194178.41 | N2: 41221.198 | O2: 62763.745 | P2: 66816.38 | Q2: 44049.065 | R2: 50970.991 | S2: 40968.602 | T2: 44873.111 | U2: 54176.539 | V2: 59575.669 | W2: 60203.527 | X2: 70405.774 | Y2: 148424.69 | Z2: 1000 | AA2: Belsport | AB2: 4 | AC2: 5 | AD2: 6 | AE2: 7 | AF2: 8 | AG2: 9 | AH2: 10 | AI2: 11 | AJ2: 12 | AK2: 13 | AL2: 14 | AM2: 15 | AN2: 16 | AO2: 17 | AP2: 18 | AQ2: 19
A3: 1001-Belsport Puente | B3: 18530.609 | C3: 34794.082 | D3: 38968.473 | E3: 27362.934 | F3: 26185.547 | G3: 26878.559 | H3: 25623.152 | I3: 34699.124 | J3: 39396.211 | K3: 31818.955 | L3: 33980.893 | M3: 91576.732 | N3: 22268.538 | O3: 36877.762 | P3: 40911.578 | Q3: 27452.904 | R3: 33696.939 | S3: 25612.041 | T3: 27443.517 | U3: 31232.672 | V3: 37661.126 | W3: 31722.14 | X3: 34625.733 | Y3: 92254.906 | Z3: 1001 | AA3: Belsport
A4: 1003-Belsport Maipu | B4: 33041.649 | C4: 62037.591 | D4: 67244.585 | E4: 47214.338 | F4: 45192.385 | G4: 46392.753 | H4: 44222.077 | I4: 59880.973 | J4: 67980.214 | K4: 54911.779 | L4: 58637.094 | M4: 157998.55 | N4: 36416.264 | O4: 75128.977 | P4: 71246.41 | Q4: 50193.862 | R4: 48465.403 | S4: 43812.042 | T4: 41348.556 | U4: 51041.225 | V4: 69916.549 | W4: 54803.916 | X4: 62542.538 | Y4: 150032.51 | Z4: 1003 | AA4: Belsport
A5: 1004-Belsport Rosas | B5: 35962.692 | C5: 67527.514 | D5: 88037.317 | E5: 61857.07 | F5: 59090.224 | G5: 60606.658 | H5: 57817.806 | I5: 78352.173 | J5: 89030.825 | K5: 71835.796 | L5: 76778.681 | M5: 207192.14 | N5: 43286.665 | O5: 69478.754 | P5: 73858.453 | Q5: 52629.457 | R5: 59370.323 | S5: 47950.898 | T5: 45525.245 | U5: 59994.218 | V5: 71556.445 | W5: 64304.204 | X5: 74993.341 | Y5: 158084.5 | Z5: 1004 | AA5: Belsport
A6: 1005-Belsport San Bernardo | B6: 25760.249 | C6: 48389.444 | D6: 63722.277 | E6: 44751.366 | F6: 42807.463 | G6: 43932.128 | H6: 41887.496 | I6: 56733.987 | J6: 64426.454 | K6: 52022.601 | L6: 55568.068 | M6: 149801.37 | N6: 28122.951 | O6: 57316.986 | P6: 65123.069 | Q6: 43299.242 | R6: 48660.688 | S6: 41508.242 | T6: 37720.807 | U6: 48784.251 | V6: 67547.596 | W6: 48840.341 | X6: 53980.289 | Y6: 129147.15 | Z6: 1005 | AA6: Belsport
A7: 1006-Belsport Vespucio I | B7: 32940.598 | C7: 61838.312 | D7: 64887.736 | E7: 45563.86 | F7: 43600.87 | G7: 44753.685 | H7: 42664.363 | I7: 57777.772 | J7: 65600.607 | K7: 52981.682 | L7: 56582.961 | M7: 152494.57 | N7: 36059.367 | O7: 70959.148 | P7: 67616.375 | Q7: 51631.802 | R7: 52872.028 | S7: 44313.623 | T7: 42848.794 | U7: 50472.918 | V7: 68583.887 | W7: 50280.589 | X7: 56157.108 | Y7: 147757.4 | Z7: 1006 | AA7: Belsport
A8: 1007-Belsport Rancagua | B8: 33185.067 | C8: 62257.794 | D8: 57487.569 | E8: 40389.326 | F8: 38590.236 | G8: 39583.968 | H8: 37759.491 | I8: 51166.105 | J8: 58134.381 | K8: 46911.65 | L8: 50135.12 | M8: 135272.98 | N8: 36741.985 | O8: 62647.257 | P8: 62573.968 | Q8: 36402.653 | R8: 37897.84 | S8: 28831.614 | T8: 29638.807 | U8: 34304.184 | V8: 48973.542 | W8: 43378.755 | X8: 48858.781 | Y8: 117112.38 | Z8: 1007 | AA8: Belsport
A9: 1008-Belsport Marina | B9: 68511.855 | C9: 128391.23 | D9: 60447.452 | E9: 42470.939 | F9: 40573.524 | G9: 41615.799 | H9: 39699.907 | I9: 53798.389 | J9: 61129.013 | K9: 49324.376 | L9: 52716.938 | M9: 142253.94 | N9: 48414.021 | O9: 66797.453 | P9: 64560.503 | Q9: 37988.673 | R9: 39444.07 | S9: 32510.945 | T9: 33938.454 | U9: 36986.562 | V9: 43967.504 | W9: 47572.722 | X9: 51319.692 | Y9: 105264.17 | Z9: 1008 | AA9: Belsport
A10: 1009-Belsport Calama | B10: 34141.345 | C10: 64059.305 | D10: 54847.091 | E10: 38512.499 | F10: 36855.644 | G10: 37831.172 | H10: 36064.092 | I10: 48838.203 | J10: 55449.048 | K10: 44784.466 | L10: 47827.179 | M10: 128891.01 | N10: 34300.554 | O10: 53989.723 | P10: 57500.197 | Q10: 41707.74 | R10: 46778.74 | S10: 38992.891 | T10: 36688.059 | U10: 42594.794 | V10: 45300.818 | W10: 46388.507 | X10: 46978.024 | Y10: 119680.98 | Z10: 1009 | AA10: Belsport
A11: 1010-Belsport Concepcion I | B11: 51638.199 | C11: 96851.188 | D11: 77719.064 | E11: 54600.767 | F11: 52175.946 | G11: 53522.816 | H11: 51052.968 | I11: 69175.665 | J11: 78591.622 | K11: 63424.607 | L11: 67778.437 | M11: 182858.35 | N11: 51740.331 | O11: 85089.077 | P11: 79257.409 | Q11: 55136.29 | R11: 52637.079 | S11: 45472.809 | T11: 46417.188 | U11: 48519.532 | V11: 62939.894 | W11: 64143.632 | X11: 66024.352 | Y11: 126647.06 | Z11: 1010 | AA11: Belsport
A12: 1012-Belsport Plaza Oeste II | B12: 17906.478 | C12: 33637.522 | D12: 44562.793 | E12: 31295.515 | F12: 29937.14 | G12: 30724.134 | H12: 29293.799 | I12: 39676.076 | J12: 45054.977 | K12: 36381.364 | L12: 38860.233 | M12: 104757.36 | N12: 26333.541 | O12: 48424.227 | P12: 46501.217 | Q12: 32938.377 | R12: 34924.371 | S12: 27361.84 | T12: 25919.556 | U12: 31448.379 | V12: 42661.565 | W12: 35748.953 | X12: 37982.3 | Y12: 99352.786 | Z12: 1012 | AA12: Belsport
A13: 1013-Belsport Los Angeles | B13: 29540.854 | C13: 55444.05 | D13: 54649.727 | E13: 38377.666 | F13: 36716.465 | G13: 37683.737 | H13: 35927.583 | I13: 48658.618 | J13: 55252.138 | K13: 44618.551 | L13: 47655.971 | M13: 128456.38 | N13: 38203.618 | O13: 70290.772 | P13: 63673.668 | Q13: 39531.918 | R13: 39741.108 | S13: 31151.721 | T13: 36943.606 | U13: 39123.632 | V13: 47135.699 | W13: 49586.448 | X13: 50937.245 | Y13: 96142.409 | Z13: 1013 | AA13: Belsport
A14: 1014-Belsport Florida Center | B14: 21444.63 | C14: 40263.646 | D14: 44630.172 | E14: 31339.307 | F14: 29988.567 | G14: 30781.212 | H14: 29344.422 | I14: 39739.678 | J14: 45120.637 | K14: 36440.847 | L14: 38918.149 | M14: 104888.33 | N14: 23498.007 | O14: 45951.211 | P14: 42499.812 | Q14: 29549.753 | R14: 31682.06 | S14: 29404.504 | T14: 27744.2 | U14: 34339.608 | V14: 47021.65 | W14: 36543.791 | X14: 41816.35 | Y14: 104019.84 | Z14: 1014 | AA14: Belsport
... A122: 8028-Aufbau Punta Arenas | B122: 7179.7946 | C122: 7614.6767 | D122: 8222.4925 | E122: 7722.6436 | F122: 6733.8507 | G122: 6988.2405 | H122: 7214.5598 | I122: 7523.519 | J122: 7106.7756 | K122: 9440.1346 | L122: 9973.436 | M122: 18668.048 | N122: 20088.87 | O122: 17938.663 | P122: 22546.054 | Q122: 17661.995 | R122: 18615.05 | S122: 14738.96 | T122: 15568.057 | U122: 1280.691 | V122: 17070.536 | W122: 26477.507 | X122: 34363.546 | Y122: 34566.045 | Z122: 8028 | AA122: Aufbau
A123: B002-Bamers Apumanque | B123: 10988.911 | C123: 9206.5532 | D123: 5506.5643 | E123: 6076.483 | F123: 13120.592 | G123: 8652.319 | H123: 7955.5066 | I123: 4022.0716 | J123: 4378.766 | K123: 6337.954 | L123: 10979.681 | M123: 24874.713 | N123: 10485.539 | O123: 6048.2023 | P123: 5067.4841 | Q123: 6060.0853 | R123: 12336.122 | S123: 6563.1116 | T123: 4981.6036 | U123: 4659.704 | V123: 5350.9582 | W123: 7973.7349 | X123: 11557.01 | Y123: 24495.656 | Z123: B002 | AA123: Bamers
A124: B003-Bamers Open Plaza Rancagu | B124: 12885.822 | C124: 10795.792 | D124: 6457.1094 | E124: 7125.4085 | F124: 15385.473 | G124: 10145.886 | H124: 9328.7893 | I124: 4716.3637 | J124: 5134.6307 | K124: 7432.0137 | L124: 12874.998 | M124: 29168.596 | N124: 12020.976 | O124: 8783.252 | P124: 6466.1895 | Q124: 10748.029 | R124: 18230.279 | S124: 8381.2632 | T124: 4851.2884 | U124: 4537.8094 | V124: 6073.932 | W124: 7837.8313 | X124: 12424.177 | Y124: 34729.946 | Z124: B003 | AA124: Bamers
A125: B004-Bamers Plaza Antofagasta | B125: 14786.726 | C125: 12388.378 | D125: 7409.6561 | E125: 8176.5422 | F125: 17655.124 | G125: 11642.597 | H125: 10704.964 | I125: 5412.117 | J125: 5892.0865 | K125: 8528.3782 | L125: 14774.306 | M125: 33471.52 | N125: 15030.123 | O125: 10152.876 | P125: 7488.6869 | Q125: 8618.2514 | R125: 16790.73 | S125: 8577.6108 | T125: 5390.5129 | U125: 5042.1905 | V125: 9249.3128 | W125: 9687.7777 | X125: 14631.129 | Y125: 46958.621 | Z125: B004 | AA125: Bamers
A126: B007-Bamers Marina Arauco | B126: 27070.51 | C126: 22679.78 | D126: 13565.084 | E126: 14969.044 | F126: 32321.774 | G126: 21314.458 | H126: 19597.902 | I126: 9908.1275 | J126: 10786.822 | K126: 15613.161 | L126: 27047.772 | M126: 61277.331 | N126: 27801.33 | O126: 20473.445 | P126: 14379.9 | Q126: 15689 | R126: 33119.277 | S126: 18016.103 | T126: 11184.1 | U126: 10461.409 | V126: 12476.328 | W126: 13264.775 | X126: 26385.533 | Y126: 61210.372 | Z126: B007 | AA126: Bamers
A127: B008-Bamers Arauco Maipu | B127: 20299.88 | C127: 17007.319 | D127: 10172.308 | E127: 11225.123 | F127: 24237.744 | G127: 15983.479 | H127: 14696.253 | I127: 7429.9969 | J127: 8088.9203 | K127: 11708.139 | L127: 20282.829 | M127: 45951.201 | N127: 18203.621 | O127: 14921.104 | P127: 10666.179 | Q127: 12439.593 | R127: 30116.334 | S127: 12573.635 | T127: 7907.4356 | U127: 7396.4755 | V127: 9667.4578 | W127: 12403.786 | X127: 19194.38 | Y127: 60018.918 | Z127: B008 | AA127: Bamers
A128: B010-Bamers Portal Osorno | B128: 12667.966 | C128: 10613.271 | D128: 6347.9411 | E128: 7004.9412 | F128: 15125.356 | G128: 9974.3526 | H128: 9171.0701 | I128: 4636.6255 | J128: 5047.8211 | K128: 7306.3635 | L128: 12657.325 | M128: 28675.452 | N128: 14274.436 | O128: 10213.646 | P128: 7244.4663 | Q128: 7894.2058 | R128: 11964.237 | S128: 9240.6027 | T128: 5364.1448 | U128: 5017.5262 | V128: 6636.6056 | W128: 7063.0892 | X128: 10003.809 | Y128: 37575.458 | Z128: B010 | AA128: Bamers
A129: B011-Bamers Plaza Tobalaba | B129: 21095.125 | C129: 17673.579 | D129: 10570.807 | E129: 11664.866 | F129: 25187.256 | G129: 16609.63 | H129: 15271.977 | I129: 7721.0664 | J129: 8405.8023 | K129: 12166.804 | L129: 21077.406 | M129: 47751.333 | N129: 18327.195 | O129: 12072.35 | P129: 10749.073 | Q129: 12199.899 | R129: 26692.887 | S129: 13015.516 | T129: 8185.6159 | U129: 7656.6804 | V129: 9392.7565 | W129: 9845.771 | X129: 18191.904 | Y129: 55007.322 | Z129: B011 | AA129: Bamers
A130: B012-Bamers Mall Center Concep | B130: 14827.502 | C130: 12422.54 | D130: 7430.0888 | E130: 8199.0892 | F130: 17703.81 | G130: 11674.703 | H130: 10734.483 | I130: 5427.0415 | J130: 5908.3347 | K130: 8551.8959 | L130: 14815.048 | M130: 33563.821 | N130: 14474.188 | O130: 8021.287 | P130: 7163.2423 | Q130: 9017.6346 | R130: 17549.555 | S130: 6328.2009 | T130: 7419.9482 | U130: 6940.4884 | V130: 8314.415 | W130: 8003.6778 | X130: 12496.765 | Y130: 33258.95 | Z130: B012 | AA130: Bamers
A131: B016-Bamers Alto Las Condes | B131: 39253.206 | C131: 32886.49 | D131: 19669.855 | E131: 21705.648 | F131: 46867.724 | G131: 30906.724 | H131: 28417.658 | I131: 14367.139 | J131: 15641.277 | K131: 22639.64 | L131: 39220.234 | M131: 88854.316 | N131: 34466.152 | O131: 19649.5 | P131: 14298.113 | Q131: 21715.02 | R131: 43204.571 | S131: 20934.384 | T131: 14921.667 | U131: 13957.464 | V131: 17145.577 | W131: 21068.38 | X131: 32592.212 | Y131: 85868.193 | Z131: B016 | AA131: Bamers
A132: B019-Bamers Portal La Reina | B132: 20713.239 | C132: 17353.634 | D132: 10379.443 | E132: 11453.696 | F132: 24731.29 | G132: 16308.945 | H132: 14995.508 | I132: 7581.291 | J132: 8253.6324 | K132: 11946.548 | L132: 20695.841 | M132: 46886.89 | N132: 20278.333 | O132: 12038.242 | P132: 10815.924 | Q132: 11724.631 | R132: 22931.646 | S132: 12633.121 | T132: 8626.1587 | U132: 8068.7564 | V132: 10425.058 | W132: 13745.79 | X132: 21615.55 | Y132: 51959.373 | Z132: B019 | AA132: Bamers
A133: B022-Bamers Plaza Egaña | B133: 18869.85 | C133: 15809.235 | D133: 9455.7168 | E133: 10434.366 | F133: 22530.311 | G133: 14857.519 | H133: 13660.972 | I133: 6906.5889 | J133: 7519.0944 | K133: 10883.356 | L133: 18854 | M133: 42714.157 | N133: 16199.071 | O133: 11901.885 | P133: 9372.9203 | Q133: 10387.646 | R133: 25003.38 | S133: 11492.113 | T133: 7019.4397 | U133: 6565.8598 | V133: 8218.127 | W133: 11119.074 | X133: 16978.737 | Y133: 47961.804 | Z133: B022 | AA133: Bamers
A134: B024-Bamers Plaza Oeste | B134: 20976.655 | C134: 17574.325 | D134: 10511.441 | E134: 11599.356 | F134: 25045.804 | G134: 16516.35 | H134: 15186.21 | I134: 7677.7047 | J134: 8358.5954 | K134: 12098.475 | L134: 20959.035 | M134: 47483.162 | N134: 18275.495 | O134: 12803.722 | P134: 9615.8223 | Q134: 13956.228 | R134: 31472.332 | S134: 15978.962 | T134: 9951.7223 | U134: 9308.6651 | V134: 8623.5398 | W134: 10841.396 | X134: 20704.233 | Y134: 51794.6 | Z134: B024 | AA134: Bamers
... A144: B056-Bamers Rosas | B144: 33227.136 | C144: 27837.826 | D144: 5506.5643 | E144: 6076.483 | F144: 13120.592 | G144: 8652.319 | H144: 7955.5066 | I144: 4022.0716 | J144: 4378.766 | K144: 6337.954 | L144: 10979.681 | M144: 24874.713 | N144: 9478.3242 | O144: 7148.409 | P144: 5607.2631 | Q144: 7511.7414 | R144: 10927.988 | S144: 7201.2762 | T144: 5552.8453 | U144: 5194.0333 | V144: 6470.6392 | W144: 8560.0242 | X144: 15891.525 | Y144: 34725.764 | Z144: B056 | AA144: Bamers
A145: B057-Bamers Puerto Varas II | B145: 0 | C145: 0 | D145: 6864.612 | E145: 7575.0861 | F145: 16356.437 | G145: 10786.183 | H145: 9917.5208 | I145: 5014.0089 | J145: 5458.6728 | K145: 7901.0413 | L145: 13687.528 | M145: 31009.399 | N145: 7198.1252 | O145: 13877.047 | P145: 9477.5341 | Q145: 9514.1958 | R145: 10965.884 | S145: 8506.8796 | T145: 7049.6761 | U145: 6594.1424 | V145: 5795.7459 | W145: 6161.8011 | X145: 5676.0833 | Y145: 22119.524 | Z145: 24 | AA145: Bamers
A146: B058-Bamers Florida Center II | B146: 0 | C146: 13491.155 | D146: 8069.2421 | E146: 8904.3936 | F146: 19226.731 | G146: 12678.988 | H146: 11657.888 | I146: 5893.8881 | J146: 6416.5827 | K146: 9287.5493 | L146: 16089.471 | M146: 36451.057 | N146: 15329.668 | O146: 9775.7598 | P146: 8655.8914 | Q146: 8838.5153 | R146: 15967.832 | S146: 10250.661 | T146: 5934.5371 | U146: 5551.0611 | V146: 6961.986 | W146: 10099.851 | X146: 16511.586 | Y146: 46095.465 | Z146: 21 | AA146: Bamers
A147: B602-Bamers Easton Center | B147: 10268.406 | C147: 7923.3028 | D147: 4804.3969 | E147: 5036.3326 | F147: 5687.4984 | G147: 4870.2809 | H147: 6049.6531 | I147: 4015.4174 | J147: 3788.0741 | K147: 5118.7717 | L147: 5858.8394 | M147: 13233.765 | N147: 7121.8508 | O147: 5179.2819 | P147: 3875.6623 | Q147: 2413.2181 | R147: 5281.1105 | S147: 4492.7237 | T147: 4001.7259 | U147: 4941.3667 | V147: 4577.9515 | W147: 5066.926 | X147: 6607.8718 | Y147: 14282.37 | Z147: B602 | AA147: Bamers
A148: B603-Bamers Buenaventura | B148: 13554.25 | C148: 10458.725 | D148: 6341.7824 | E148: 6647.9364 | F148: 7507.4722 | G148: 6428.7489 | H148: 7985.5151 | I148: 5300.3328 | J148: 5000.2407 | K148: 6756.7559 | L148: 7733.6417 | M148: 17468.51 | N148: 8725.7988 | O148: 7125.5308 | P148: 4704.9695 | Q148: 3911.6886 | R148: 6651.6558 | S148: 6691.6882 | T148: 6425.4412 | U148: 6749.6994 | V148: 7745.0642 | W148: 7183.9966 | X148: 9585.0921 | Y148: 22829.352 | Z148: B603 | AA148: Bamers
A149: D002-Oakley Costanera Center | B149: 23389.711 | C149: 24415.368 | D149: 17236.829 | E149: 18956.882 | F149: 18659.801 | G149: 24599.278 | H149: 26930.348 | I149: 22428.816 | J149: 24735.035 | K149: 29447.184 | L149: 23580.658 | M149: 48702.534 | N149: 25820.452 | O149: 23295.462 | P149: 31985.098 | Q149: 25773.551 | R149: 26038.405 | S149: 30989.055 | T149: 28678.628 | U149: 31678.437 | V149: 25952.571 | W149: 24924.907 | X149: 31036.036 | Y149: 63564.65 | Z149: D002 | AA149: Oakley
A150: D004-Oakley Alto Las Condes | B150: 16461.287 | C150: 17183.128 | D150: 12715.236 | E150: 9247.9849 | F150: 11373.154 | G150: 17190.084 | H150: 17113.649 | I150: 10931.89 | J150: 13023.635 | K150: 19653.466 | L150: 10873.55 | M150: 38069.635 | N150: 18044.855 | O150: 12624.394 | P150: 16064.558 | Q150: 14288.305 | R150: 16718.968 | S150: 20816.426 | T150: 17253.76 | U150: 17901.312 | V150: 14791.905 | W150: 15287.993 | X150: 18416.095 | Y150: 53685.618 | Z150: D004 | AA150: Oakley
A151: D011-Oakley Marina | B151: 24262.981 | C151: 25326.932 | D151: 13865.408 | E151: 11385.626 | F151: 13403.779 | G151: 12037.297 | H151: 16187.431 | I151: 11283.883 | J151: 15588.793 | K151: 18087.133 | L151: 13215.255 | M151: 35089.451 | N151: 26956.01 | O151: 17488.307 | P151: 20825.848 | Q151: 13767.205 | R151: 17456.781 | S151: 12877.913 | T151: 13188.625 | U151: 16202.581 | V151: 15572.191 | W151: 18576.785 | X151: 22599.21 | Y151: 47930.115 | Z151: D011 | AA151: Oakley
A152: D012-Oakley Antofagasta | B152: 13256.32 | C152: 13837.62 | D152: 12620.374 | E152: 10439.15 | F152: 12400.545 | G152: 20648.816 | H152: 16789.9 | I152: 12843.804 | J152: 12616.953 | K152: 18546.314 | L152: 12200.544 | M152: 41232.737 | N152: 15727.861 | O152: 14652.622 | P152: 20626.899 | Q152: 11427.985 | R152: 13171.669 | S152: 17824.798 | T152: 12111.064 | U152: 19946.465 | V152: 14964.236 | W152: 17403.208 | X152: 20038.92 | Y152: 56098.254 | Z152: D012 | AA152: Oakley
A153: D013-Oakley Puerto Montt | B153: 19488.438 | C153: 20343.022 | D153: 9220.2004 | E153: 7843.6368 | F153: 7661.5449 | G153: 11916.233 | H153: 10829.512 | I153: 8776.3518 | J153: 8977.6979 | K153: 12885.19 | L153: 10075.891 | M153: 20061.194 | N153: 20104.974 | O153: 15506.69 | P153: 17719.959 | Q153: 12392.546 | R153: 10258.411 | S153: 10411.341 | T153: 9841.0315 | U153: 13656.421 | V153: 9419.6081 | W153: 11136.616 | X153: 12666.951 | Y153: 30188.734 | Z153: D013 | AA153: Oakley
A154: D014-Oakley Parque Arauco | B154: 19412.972 | C154: 20264.246 | D154: 18906.316 | E154: 13963.945 | F154: 17838.459 | G154: 28014.309 | H154: 24428.888 | I154: 16949.557 | J154: 17039.123 | K154: 26720.754 | L154: 22605.277 | M154: 47401.413 | N154: 22910.271 | O154: 20461.24 | P154: 26365.603 | Q154: 22646.204 | R154: 23913.668 | S154: 25582.388 | T154: 26812.228 | U154: 25541.03 | V154: 18661.773 | W154: 22531.667 | X154: 28938.942 | Y154: 64036.933 | Z154: D014 | AA154: Oakley
A155: E001-Oakley Portal Rancagua | B155: 8661.312 | C155: 10808.226 | D155: 8061.7788 | E155: 4245.2471 | F155: 4832.8325 | G155: 9545.7172 | H155: 10123.546 | I155: 8526.2376 | J155: 9497.1824 | K155: 12007.358 | L155: 7395.2254 | M155: 21177.011 | N155: 9918.787 | O155: 10407.864 | P155: 10180.486 | Q155: 10105.801 | R155: 9428.7503 | S155: 9429.1833 | T155: 7770.162 | U155: 12242.866 | V155: 9964.6632 | W155: 10886.662 | X155: 14316.124 | Y155: 36940.235 | Z155: E001 | AA155: Oakley
A156: E002-Oakley El Trebol | B156: 11174.949 | C156: 11641.784 | D156: 9793.2915 | E156: 7813.4076 | F156: 8157.7811 | G156: 12661.043 | H156: 16515.155 | I156: 9733.0052 | J156: 10306.088 | K156: 10618.7 | L156: 8277.7691 | M156: 28110.793 | N156: 12797.362 | O156: 11642.187 | P156: 12608.916 | Q156: 12894.399 | R156: 11875.261 | S156: 11967.318 | T156: 11912.882 | U156: 13975.669 | V156: 11648.582 | W156: 11374.254 | X156: 15267.084 | Y156: 42312.39 | Z156: E002 | AA156: Oakley
...

Sheet Costo Real
A1: Sucursal | B1: 45658 | C1: 45689 | D1: 45717 | E1: 45748 | F1: 45778 | G1: 45809 | H1: 45839 | I1: 45870 | J1: 45901 | K1: 45931 | L1: 45962 | M1: 45992 | N1: 46023 | O1: 46054 | P1: 46082 | Q1: 46113 | R1: 46143 | S1: 46174 | T1: 46204 | U1: 46235 | V1: 46266 | W1: 46296 | X1: 46327 | Y1: 46357 | AA1: Banner
A2: 1000-Belsport Ahumada | B2: -55539.458 | C2: -77752.712 | D2: -78516.162 | E2: -53575.755 | F2: -64959.003 | G2: -50827.055 | H2: -72516.217 | I2: -61306.189 | J2: -82723.285 | K2: 0 | Z2: 1000 | AA2: Belsport | AB2: 1000 | AC2: 1001 | AD2: 1002 | AE2: 1003 | AF2: 1004 | AG2: 1005 | AH2: 1006 | AI2: 1007 | AJ2: 1008 | AK2: 1009 | AL2: 1010 | AM2: 1011 | AN2: 1012 | AO2: 1013 | AP2: 1014 | AQ2: 1015
A3: 1001-Belsport Puente | B3: -29188.55 | C3: -43276.157 | D3: -48072.582 | E3: -33558.043 | F3: -40608.755 | G3: -31081.797 | H3: -38823.793 | I3: -36457.16 | J3: -46870.262 | K3: 0 | Z3: 1001 | AA3: Belsport | AB3: 1001
A4: 1003-Belsport Maipu | B4: -45591.901 | C4: -81688.851 | D4: -83066.824 | E4: -56659.386 | F4: -59200.183 | G4: -47779.275 | H4: -54944.232 | I4: -66400.604 | J4: -77924.288 | K4: 0 | Z4: 1003 | AA4: Belsport | AB4: 1003
A5: 1004-Belsport Rosas | B5: -58963.601 | C5: -85642.179 | D5: -86376.613 | E5: -67088.893 | F5: -76896.145 | G5: -51498.504 | H5: -69127.708 | I5: -71491.503 | J5: -86105.057 | K5: 0 | Z5: 1004 | AA5: Belsport | AB5: 1004
A6: 1005-Belsport San Bernardo | B6: -40122.219 | C6: -73291.228 | D6: -77449.682 | E6: -52391.4 | F6: -62287.312 | G6: -50585.892 | H6: -58714.809 | I6: -64066.454 | J6: -88146.49 | K6: 0 | Z6: 1005 | AA6: Belsport | AB6: 1005
A7: 1006-Belsport Vespucio I | B7: -45782.716 | C7: -81834.558 | D7: -77688.84 | E7: -50493.723 | F7: -64934.486 | G7: -50082.902 | H7: -57636.923 | I7: -65951.37 | J7: -96423.326 | K7: 0 | Z7: 1006 | AA7: Belsport | AB7: 1006
A8: 1007-Belsport Rancagua | B8: -44079.73 | C8: -77229.364 | D8: -62080.875 | E8: -39735.37 | F8: -45054.571 | G8: -31455.505 | H8: -44577.706 | I8: -50022.235 | J8: -70540.772 | K8: 0 | Z8: 1007 | AA8: Belsport | AB8: 1007
A9: 1008-Belsport Marina | B9: -88179.778 | C9: -86887.436 | D9: -74869.181 | E9: -53186.072 | F9: -50611.451 | G9: -35879.19 | H9: -41320.59 | I9: -46283.217 | J9: -61062.844 | K9: 0 | Z9: 1008 | AA9: Belsport | AB9: 1008
A10: 1009-Belsport Calama | B10: -46048.007 | C10: -62640.295 | D10: -68285.758 | E10: -52131.708 | F10: -57745.519 | G10: -46062.965 | H10: -51216.164 | I10: -53759.111 | J10: -52851.282 | K10: 0 | Z10: 1009 | AA10: Belsport | AB10: 1009
A11: 1010-Belsport Concepcion I | B11: -69473.739 | C11: -101769.51 | D11: -82749.339 | E11: -57794.656 | F11: -65103.121 | G11: -46199.386 | H11: -56613.026 | I11: -63024.138 | J11: -86393.908 | K11: 0 | Z11: 1010 | AA11: Belsport | AB11: 1010
A12: 1012-Belsport Plaza Oeste II | B12: -30971.873 | C12: -56181.136 | D12: -55217.062 | E12: -37253.094 | F12: -43381.715 | G12: -29548.131 | H12: -36290.393 | I12: -42790.935 | J12: -54820.805 | K12: 0 | Z12: 1012 | AA12: Belsport | AB12: 1012
A13: 1013-Belsport Los Angeles | B13: -47508.624 | C13: -79658.425 | D13: -70140.723 | E13: -46463.514 | F13: -50094.52 | G13: -32219.05 | H13: -48396.069 | I13: -52409.132 | J13: -70089.396 | K13: 0 | Z13: 1013 | AA13: Belsport | AB13: 1013
A14: 1014-Belsport Florida Center | B14: -29354.528 | C14: -49175.635 | D14: -44928.532 | E14: -28706.722 | F14: -38417.263 | G14: -31614.829 | H14: -38931.096 | I14: -38822.023 | J14: -49316.746 | K14: 0 | Z14: 1014 | AA14: Belsport | AB14: 1014
... A122: 8028-Aufbau Punta Arenas | B122: -125143.71 | C122: -101371.49 | D122: -108961.68 | E122: -87339.143 | F122: -95035.966 | G122: -67033 | H122: -85925.079 | I122: -73279.481 | J122: -111296.03 | K122: 0 | Z122: 8028 | AA122: Aufbau | AB122: 8028
A123: B002-Bamers Apumanque | B123: -4524.627 | C123: -2492.3415 | D123: -2118.3985 | E123: -2358.9798 | F123: -4309.3743 | G123: -2435.3483 | H123: -3417.6574 | I123: -3017.365 | J123: -2680.4187 | K123: 0 | Z123: B002 | AA123: Bamers | AB123: B002
A124: B003-Bamers Open Plaza Rancagu | B124: -6206.98 | C124: -4111.572 | D124: -3586.495 | E124: -4391.547 | F124: -7028.9357 | G124: -3519.2824 | H124: -2957.8988 | I124: -4180.7761 | J124: -3269.6104 | K124: 0 | Z124: B003 | AA124: Bamers | AB124: B003
A125: B004-Bamers Plaza Antofagasta | B125: -7636.397 | C125: -4154.345 | D125: -3596.1875 | E125: -3748.287 | F125: -6457.6307 | G125: -3391.5453 | H125: -4700.3969 | I125: -5049.5285 | J125: -4286.587 | K125: 0 | Z125: B004 | AA125: Bamers | AB125: B004
A126: B007-Bamers Marina Arauco | B126: -14567.878 | C126: -9180.525 | D126: -7311.967 | E126: -6306.629 | F126: -12829.426 | G126: -6533.7239 | H126: -7729.7928 | I126: -7796.2099 | J126: -5492.799 | K126: 0 | Z126: B007 | AA126: Bamers | AB126: B007
A127: B008-Bamers Arauco Maipu | B127: -10317.453 | C127: -7110.3 | D127: -5992.237 | E127: -5053.2041 | F127: -10977.749 | G127: -5420.3564 | H127: -6248.8309 | I127: -6527.4706 | J127: -3925.7971 | K127: 0 | Z127: B008 | AA127: Bamers | AB127: B008
A128: B010-Bamers Portal Osorno | B128: -7184.6653 | C128: -4313.555 | D128: -3638.7687 | E128: -3103.5277 | F128: -5347.9613 | G128: -3856.4845 | H128: -4362.063 | I128: -3823.096 | J128: -4113.326 | K128: 0 | Z128: B010 | AA128: Bamers | AB128: B010
A129: B011-Bamers Plaza Tobalaba | B129: -8090.0677 | C129: -5140.219 | D129: -4597.155 | E129: -4158.848 | F129: -9392.9426 | G129: -5656.25 | H129: -5966.2233 | I129: -8685.807 | J129: -3804.732 | K129: 0 | Z129: B011 | AA129: Bamers | AB129: B011
A130: B012-Bamers Mall Center Concep | B130: -6352.483 | C130: -3013.821 | D130: -2665.003 | E130: -3519.182 | F130: -6280.9209 | G130: -2231.1195 | H130: -3736.486 | I130: -3033.7334 | J130: -2422.392 | K130: 0 | Z130: B012 | AA130: Bamers | AB130: B012
A131: B016-Bamers Alto Las Condes | B131: -15774.249 | C131: -7750.896 | D131: -6948.591 | E131: -8515.98 | F131: -14843.65 | G131: -8352.1999 | H131: -420.103 | I131: 0 | J131: 0 | K131: 0 | Z131: B016 | AA131: Bamers | AB131: B016
A132: B019-Bamers Portal La Reina | B132: -8747.1775 | C132: -5080.669 | D132: -4857.37 | E132: -4490.7635 | F132: -7857.4544 | G132: -4811.1071 | H132: -6490.0889 | I132: -6313.1655 | J132: -4385.5622 | K132: 0 | Z132: B019 | AA132: Bamers | AB132: B019
A133: B022-Bamers Plaza Egaña | B133: -7221.4558 | C133: -5159.344 | D133: -3932.642 | E133: -3908.4569 | F133: -8057.9441 | G133: -4484.744 | H133: -4872.394 | I133: -5078.9225 | J133: -3946.5867 | K133: 0 | Z133: B022 | AA133: Bamers | AB133: B022
A134: B024-Bamers Plaza Oeste | B134: -8578.2725 | C134: -4798.509 | D134: -3882.8902 | E134: -5342.3608 | F134: -12381.323 | G134: -5705.0603 | H134: -6431.0351 | I134: -4882.4724 | J134: -3220.52 | K134: 0 | Z134: B024 | AA134: Bamers | AB134: B024
... A159: B023-Bamers Florida Center | B159: 0 | C159: 0 | D159: 0 | E159: 0 | F159: 0 | G159: 0 | H159: 0 | I159: 0 | J159: 0 | K159: 0 | Z159: B006 | AA159: Bamers | AB159: B006
A160: 2001-Bold Plaza Vespucio | B160: -65313.06 | C160: -92244.814 | D160: -83607.543 | E160: -62289.63 | F160: -75849.052 | G160: -54866.999 | H160: -57710.515 | I160: -39553.719 | J160: 0 | K160: 0 | Z160: 2001 | AA160: Bold | AB160: 2001
A161: 1011-Belsport Puerto Montt | B161: -72186.49 | C161: -97568.879 | D161: -71893.188 | E161: -52064.332 | F161: -52175.594 | G161: -38725.469 | H161: -40496.76 | I161: -44908.77 | J161: -47836.379 | K161: 0 | Z161: 1011 | AA161: Belsport | AB161: 1011
A162: 5002-Drops MUT | B162: 0 | C162: 0 | D162: 0 | E162: 0 | F162: 0 | G162: 0 | H162: 0 | I162: 0 | J162: 0 | K162: 0 | AA162: Drops
A163: 2037-Bold Vespucio III | B163: 0 | C163: 0 | D163: 0 | E163: 0 | F163: 0 | G163: 0 | H163: 0 | I163: -121907.19 | J163: -298131.83 | K163: 0 | Z163: 2037 | AA163: Bold | AB163: 2037
A164: 7502-Hoka Marina | B164: 0 | C164: 0 | D164: 0 | E164: 0 | F164: 0 | G164: 0 | H164: 0 | I164: 0 | J164: 0 | K164: 0 | Z164: 7502 | AA164: Hoka | AB164: #N/A
A165: Bamers X | B165: 0 | C165: 0 | D165: 0 | E165: 0 | F165: 0 | G165: 0 | H165: 0 | I165: 0 | J165: 0 | K165: 0 | AA165: Bamers
A166: Bamers Y | B166: 0 | C166: 0 | D166: 0 | E166: 0 | F166: 0 | G166: 0 | H166: 0 | I166: 0 | J166: 0 | K166: 0 | AA166: Bamers
A167: Apple Puerto Varas | B167: 0 | C167: 0 | D167: 0 | E167: 0 | F167: 0 | G167: 0 | H167: 0 | I167: 0 | J167: 0 | K167: 0 | AA167: Aufbau
A168: Hoka Parque Arauco | B168: 0 | C168: 0 | D168: 0 | E168: 0 | F168: 0 | G168: 0 | H168: 0 | I168: 0 | J168: 0 | K168: 0 | Z168: 7503 | AA168: Hoka | AB168: #N/A
A169: Drops Parque Arauco | B169: 0 | C169: 0 | D169: 0 | E169: 0 | F169: 0 | G169: 0 | H169: 0 | I169: 0 | J169: 0 | K169: 0 | Z169: 5003 | AA169: Drops | AB169: #N/A
B170: 0 | C170: 0 | D170: 0 | E170: 0 | F170: 0 | G170: 0 | H170: 0 | I170: 0 | J170: 0 | K170: 0
B171: 0 | C171: 0 | D171: 0 | E171: 0 | F171: 0 | G171: 0 | H171: 0 | I171: 0 | J171: 0 | K171: 0
...

Sheet Contri Real
A1: Sucursal | B1: 45658 | C1: 45689 | D1: 45717 | E1: 45748 | F1: 45778 | G1: 45809 | H1: 45839 | I1: 45870 | J1: 45901 | K1: 45931 | L1: 45962 | M1: 45992 | N1: 46023 | O1: 46054 | P1: 46082 | Q1: 46113 | R1: 46143 | S1: 46174 | T1: 46204 | U1: 46235 | V1: 46266 | W1: 46296 | X1: 46327 | Y1: 46357 | AA1: Banner
A2: 1000-Belsport Ahumada | B2: =+REAL_Venta!B2+'Costo Real'!B2 -> 38902.612 | C2: =+REAL_Venta!C2+'Costo Real'!C2 -> 58609.975 | D2: =+REAL_Venta!D2+'Costo Real'!D2 -> 61252.582 | E2: =+REAL_Venta!E2+'Costo Real'!E2 -> 41910.767 | F2: =+REAL_Venta!F2+'Costo Real'!F2 -> 40312.442 | G2: =+REAL_Venta!G2+'Costo Real'!G2 -> 27274.817 | H2: =+REAL_Venta!H2+'Costo Real'!H2 -> 36148.39 | I2: =+REAL_Venta!I2+'Costo Real'!I2 -> 41343.9 | J2: =+REAL_Venta!J2+'Costo Real'!J2 -> 39388.491 | Z2: 1000 | AA2: Belsport | AB2: 1000 | AC2: 1001 | AD2: 1002 | AE2: 1003 | AF2: 1004 | AG2: 1005 | AH2: 1006 | AI2: 1007 | AJ2: 1008 | AK2: 1009 | AL2: 1010 | AM2: 1011 | AN2: 1012 | AO2: 1013 | AP2: 1014 | AQ2: 1015
A3: 1001-Belsport Puente | B3: =+REAL_Venta!B3+'Costo Real'!B3 -> 19492.189 | C3: =+REAL_Venta!C3+'Costo Real'!C3 -> 32890.946 | D3: =+REAL_Venta!D3+'Costo Real'!D3 -> 36996.967 | E3: =+REAL_Venta!E3+'Costo Real'!E3 -> 24705.856 | F3: =+REAL_Venta!F3+'Costo Real'!F3 -> 25653.144 | G3: =+REAL_Venta!G3+'Costo Real'!G3 -> 16982.025 | H3: =+REAL_Venta!H3+'Costo Real'!H3 -> 17711.557 | I3: =+REAL_Venta!I3+'Costo Real'!I3 -> 20292.522 | J3: =+REAL_Venta!J3+'Costo Real'!J3 -> 24066.033 | Z3: 1001 | AA3: Belsport | AB3: 1001
A4: 1003-Belsport Maipu | B4: =+REAL_Venta!B4+'Costo Real'!B4 -> 34277.242 | C4: =+REAL_Venta!C4+'Costo Real'!C4 -> 65504.381 | D4: =+REAL_Venta!D4+'Costo Real'!D4 -> 65572.677 | E4: =+REAL_Venta!E4+'Costo Real'!E4 -> 43692.741 | F4: =+REAL_Venta!F4+'Costo Real'!F4 -> 43086.774 | G4: =+REAL_Venta!G4+'Costo Real'!G4 -> 29435.954 | H4: =+REAL_Venta!H4+'Costo Real'!H4 -> 33469.666 | I4: =+REAL_Venta!I4+'Costo Real'!I4 -> 47955.505 | J4: =+REAL_Venta!J4+'Costo Real'!J4 -> 47897.775 | Z4: 1003 | AA4: Belsport | AB4: 1003
A5: 1004-Belsport Rosas | B5: =+REAL_Venta!B5+'Costo Real'!B5 -> 41274.174 | C5: =+REAL_Venta!C5+'Costo Real'!C5 -> 66320.247 | D5: =+REAL_Venta!D5+'Costo Real'!D5 -> 67778.338 | E5: =+REAL_Venta!E5+'Costo Real'!E5 -> 50789.879 | F5: =+REAL_Venta!F5+'Costo Real'!F5 -> 48614.951 | G5: =+REAL_Venta!G5+'Costo Real'!G5 -> 33009.973 | H5: =+REAL_Venta!H5+'Costo Real'!H5 -> 38989.876 | I5: =+REAL_Venta!I5+'Costo Real'!I5 -> 51513.516 | J5: =+REAL_Venta!J5+'Costo Real'!J5 -> 53043.227 | Z5: 1004 | AA5: Belsport | AB5: 1004
A6: 1005-Belsport San Bernardo | B6: =+REAL_Venta!B6+'Costo Real'!B6 -> 25183.596 | C6: =+REAL_Venta!C6+'Costo Real'!C6 -> 52428.8 | D6: =+REAL_Venta!D6+'Costo Real'!D6 -> 58260.1 | E6: =+REAL_Venta!E6+'Costo Real'!E6 -> 37890.56 | F6: =+REAL_Venta!F6+'Costo Real'!F6 -> 40415.542 | G6: =+REAL_Venta!G6+'Costo Real'!G6 -> 30412.361 | H6: =+REAL_Venta!H6+'Costo Real'!H6 -> 32913.883 | I6: =+REAL_Venta!I6+'Costo Real'!I6 -> 44007.003 | J6: =+REAL_Venta!J6+'Costo Real'!J6 -> 51769.76 | Z6: 1005 | AA6: Belsport | AB6: 1005
A7: 1006-Belsport Vespucio I | B7: =+REAL_Venta!B7+'Costo Real'!B7 -> 33403.258 | C7: =+REAL_Venta!C7+'Costo Real'!C7 -> 64391.467 | D7: =+REAL_Venta!D7+'Costo Real'!D7 -> 62816.202 | E7: =+REAL_Venta!E7+'Costo Real'!E7 -> 40677.938 | F7: =+REAL_Venta!F7+'Costo Real'!F7 -> 46737.231 | G7: =+REAL_Venta!G7+'Costo Real'!G7 -> 34294.359 | H7: =+REAL_Venta!H7+'Costo Real'!H7 -> 36762.666 | I7: =+REAL_Venta!I7+'Costo Real'!I7 -> 49175.941 | J7: =+REAL_Venta!J7+'Costo Real'!J7 -> 58701.084 | Z7: 1006 | AA7: Belsport | AB7: 1006
A8: 1007-Belsport Rancagua | B8: =+REAL_Venta!B8+'Costo Real'!B8 -> 31432.132 | C8: =+REAL_Venta!C8+'Costo Real'!C8 -> 57518.418 | D8: =+REAL_Venta!D8+'Costo Real'!D8 -> 48419.432 | E8: =+REAL_Venta!E8+'Costo Real'!E8 -> 31380.062 | F8: =+REAL_Venta!F8+'Costo Real'!F8 -> 33609.967 | G8: =+REAL_Venta!G8+'Costo Real'!G8 -> 23116.449 | H8: =+REAL_Venta!H8+'Costo Real'!H8 -> 25870.592 | I8: =+REAL_Venta!I8+'Costo Real'!I8 -> 36736.393 | J8: =+REAL_Venta!J8+'Costo Real'!J8 -> 40411.422 | Z8: 1007 | AA8: Belsport | AB8: 1007
A9: 1008-Belsport Marina | B9: =+REAL_Venta!B9+'Costo Real'!B9 -> 62138.464 | C9: =+REAL_Venta!C9+'Costo Real'!C9 -> 68435.119 | D9: =+REAL_Venta!D9+'Costo Real'!D9 -> 59652.716 | E9: =+REAL_Venta!E9+'Costo Real'!E9 -> 39727.579 | F9: =+REAL_Venta!F9+'Costo Real'!F9 -> 32462.83 | G9: =+REAL_Venta!G9+'Costo Real'!G9 -> 20054.437 | H9: =+REAL_Venta!H9+'Costo Real'!H9 -> 26986.829 | I9: =+REAL_Venta!I9+'Costo Real'!I9 -> 34048.462 | J9: =+REAL_Venta!J9+'Costo Real'!J9 -> 33119.464 | Z9: 1008 | AA9: Belsport | AB9: 1008
A10: 1009-Belsport Calama | B10: =+REAL_Venta!B10+'Costo Real'!B10 -> 33220.402 | C10: =+REAL_Venta!C10+'Costo Real'!C10 -> 47419.339 | D10: =+REAL_Venta!D10+'Costo Real'!D10 -> 51327.975 | E10: =+REAL_Venta!E10+'Costo Real'!E10 -> 39031.765 | F10: =+REAL_Venta!F10+'Costo Real'!F10 -> 40949.363 | G10: =+REAL_Venta!G10+'Costo Real'!G10 -> 27792.552 | H10: =+REAL_Venta!H10+'Costo Real'!H10 -> 31413.652 | I10: =+REAL_Venta!I10+'Costo Real'!I10 -> 37132.306 | J10: =+REAL_Venta!J10+'Costo Real'!J10 -> 32153.815 | Z10: 1009 | AA10: Belsport | AB10: 1009
A11: 1010-Belsport Concepcion I | B11: =+REAL_Venta!B11+'Costo Real'!B11 -> 50901.951 | C11: =+REAL_Venta!C11+'Costo Real'!C11 -> 79327.59 | D11: =+REAL_Venta!D11+'Costo Real'!D11 -> 65863.629 | E11: =+REAL_Venta!E11+'Costo Real'!E11 -> 45104.361 | F11: =+REAL_Venta!F11+'Costo Real'!F11 -> 46068.228 | G11: =+REAL_Venta!G11+'Costo Real'!G11 -> 30797.76 | H11: =+REAL_Venta!H11+'Costo Real'!H11 -> 31341.03 | I11: =+REAL_Venta!I11+'Costo Real'!I11 -> 44056.485 | J11: =+REAL_Venta!J11+'Costo Real'!J11 -> 43878.451 | Z11: 1010 | AA11: Belsport | AB11: 1010
A12: 1012-Belsport Plaza Oeste II | B12: =+REAL_Venta!B12+'Costo Real'!B12 -> 22092.311 | C12: =+REAL_Venta!C12+'Costo Real'!C12 -> 44001.737 | D12: =+REAL_Venta!D12+'Costo Real'!D12 -> 41655.271 | E12: =+REAL_Venta!E12+'Costo Real'!E12 -> 29077.2 | F12: =+REAL_Venta!F12+'Costo Real'!F12 -> 30066.991 | G12: =+REAL_Venta!G12+'Costo Real'!G12 -> 16691.32 | H12: =+REAL_Venta!H12+'Costo Real'!H12 -> 20852.953 | I12: =+REAL_Venta!I12+'Costo Real'!I12 -> 28163.88 | J12: =+REAL_Venta!J12+'Costo Real'!J12 -> 32042.624 | Z12: 1012 | AA12: Belsport | AB12: 1012
A13: 1013-Belsport Los Angeles | B13: =+REAL_Venta!B13+'Costo Real'!B13 -> 33716.213 | C13: =+REAL_Venta!C13+'Costo Real'!C13 -> 60343.09 | D13: =+REAL_Venta!D13+'Costo Real'!D13 -> 54117.454 | E13: =+REAL_Venta!E13+'Costo Real'!E13 -> 36474.986 | F13: =+REAL_Venta!F13+'Costo Real'!F13 -> 34005.345 | G13: =+REAL_Venta!G13+'Costo Real'!G13 -> 21760.077 | H13: =+REAL_Venta!H13+'Costo Real'!H13 -> 27041.529 | I13: =+REAL_Venta!I13+'Costo Real'!I13 -> 36683.261 | J13: =+REAL_Venta!J13+'Costo Real'!J13 -> 37209.376 | Z13: 1013 | AA13: Belsport | AB13: 1013
A14: 1014-Belsport Florida Center | B14: =+REAL_Venta!B14+'Costo Real'!B14 -> 20397.286 | C14: =+REAL_Venta!C14+'Costo Real'!C14 -> 37648.532 | D14: =+REAL_Venta!D14+'Costo Real'!D14 -> 34543.624 | E14: =+REAL_Venta!E14+'Costo Real'!E14 -> 21712.843 | F14: =+REAL_Venta!F14+'Costo Real'!F14 -> 24980.566 | G14: =+REAL_Venta!G14+'Costo Real'!G14 -> 16303.963 | H14: =+REAL_Venta!H14+'Costo Real'!H14 -> 20081.615 | I14: =+REAL_Venta!I14+'Costo Real'!I14 -> 23009.643 | J14: =+REAL_Venta!J14+'Costo Real'!J14 -> 26201.562 | Z14: 1014 | AA14: Belsport | AB14: 1014
... A122: 8028-Aufbau Punta Arenas | B122: =+REAL_Venta!B122+'Costo Real'!B122 -> 21322.366 | C122: =+REAL_Venta!C122+'Costo Real'!C122 -> 18954.912 | D122: =+REAL_Venta!D122+'Costo Real'!D122 -> 18979.144 | E122: =+REAL_Venta!E122+'Costo Real'!E122 -> 16438.986 | F122: =+REAL_Venta!F122+'Costo Real'!F122 -> 16341.132 | G122: =+REAL_Venta!G122+'Costo Real'!G122 -> 11521.45 | H122: =+REAL_Venta!H122+'Costo Real'!H122 -> 14806.484 | I122: =+REAL_Venta!I122+'Costo Real'!I122 -> 13016.084 | J122: =+REAL_Venta!J122+'Costo Real'!J122 -> 15943.543 | Z122: 8028 | AA122: Aufbau | AB122: 8028
A123: B002-Bamers Apumanque | B123: =+REAL_Venta!B123+'Costo Real'!B123 -> 7171.9301 | C123: =+REAL_Venta!C123+'Costo Real'!C123 -> 3658.9047 | D123: =+REAL_Venta!D123+'Costo Real'!D123 -> 3427.2553 | E123: =+REAL_Venta!E123+'Costo Real'!E123 -> 4643.9261 | F123: =+REAL_Venta!F123+'Costo Real'!F123 -> 8025.3156 | G123: =+REAL_Venta!G123+'Costo Real'!G123 -> 4984.0013 | H123: =+REAL_Venta!H123+'Costo Real'!H123 -> 3938.2359 | I123: =+REAL_Venta!I123+'Costo Real'!I123 -> 3252.8014 | J123: =+REAL_Venta!J123+'Costo Real'!J123 -> 4136.9931 | Z123: B002 | AA123: Bamers | AB123: B002
A124: B003-Bamers Open Plaza Rancagu | B124: =+REAL_Venta!B124+'Costo Real'!B124 -> 9980.8914 | C124: =+REAL_Venta!C124+'Costo Real'!C124 -> 5973.8557 | D124: =+REAL_Venta!D124+'Costo Real'!D124 -> 4935.6546 | E124: =+REAL_Venta!E124+'Costo Real'!E124 -> 8028.6471 | F124: =+REAL_Venta!F124+'Costo Real'!F124 -> 11999.53 | G124: =+REAL_Venta!G124+'Costo Real'!G124 -> 6546.8613 | H124: =+REAL_Venta!H124+'Costo Real'!H124 -> 3185.813 | I124: =+REAL_Venta!I124+'Costo Real'!I124 -> 3252.7777 | J124: =+REAL_Venta!J124+'Costo Real'!J124 -> 3889.7871 | Z124: B003 | AA124: Bamers | AB124: B003
A125: B004-Bamers Plaza Antofagasta | B125: =+REAL_Venta!B125+'Costo Real'!B125 -> 12044.428 | C125: =+REAL_Venta!C125+'Costo Real'!C125 -> 6989.8021 | D125: =+REAL_Venta!D125+'Costo Real'!D125 -> 6273.568 | E125: =+REAL_Venta!E125+'Costo Real'!E125 -> 6210.7811 | F125: =+REAL_Venta!F125+'Costo Real'!F125 -> 12684.805 | G125: =+REAL_Venta!G125+'Costo Real'!G125 -> 6812.8143 | H125: =+REAL_Venta!H125+'Costo Real'!H125 -> 6114.8224 | I125: =+REAL_Venta!I125+'Costo Real'!I125 -> 7407.2236 | J125: =+REAL_Venta!J125+'Costo Real'!J125 -> 8195.8752 | Z125: B004 | AA125: Bamers | AB125: B004
A126: B007-Bamers Marina Arauco | B126: =+REAL_Venta!B126+'Costo Real'!B126 -> 23974.511 | C126: =+REAL_Venta!C126+'Costo Real'!C126 -> 13937.145 | D126: =+REAL_Venta!D126+'Costo Real'!D126 -> 11640.101 | E126: =+REAL_Venta!E126+'Costo Real'!E126 -> 11823.247 | F126: =+REAL_Venta!F126+'Costo Real'!F126 -> 23739.81 | G126: =+REAL_Venta!G126+'Costo Real'!G126 -> 13493.416 | H126: =+REAL_Venta!H126+'Costo Real'!H126 -> 8293.4047 | I126: =+REAL_Venta!I126+'Costo Real'!I126 -> 6259.6305 | J126: =+REAL_Venta!J126+'Costo Real'!J126 -> 8039.5817 | Z126: B007 | AA126: Bamers | AB126: B007
A127: B008-Bamers Arauco Maipu | B127: =+REAL_Venta!B127+'Costo Real'!B127 -> 13458.209 | C127: =+REAL_Venta!C127+'Costo Real'!C127 -> 9029.8496 | D127: =+REAL_Venta!D127+'Costo Real'!D127 -> 8065.3117 | E127: =+REAL_Venta!E127+'Costo Real'!E127 -> 9321.7253 | F127: =+REAL_Venta!F127+'Costo Real'!F127 -> 19462.288 | G127: =+REAL_Venta!G127+'Costo Real'!G127 -> 10001.374 | H127: =+REAL_Venta!H127+'Costo Real'!H127 -> 7063.5203 | I127: =+REAL_Venta!I127+'Costo Real'!I127 -> 5256.1916 | J127: =+REAL_Venta!J127+'Costo Real'!J127 -> 6410.0911 | Z127: B008 | AA127: Bamers | AB127: B008
A128: B010-Bamers Portal Osorno | B128: =+REAL_Venta!B128+'Costo Real'!B128 -> 10436.763 | C128: =+REAL_Venta!C128+'Costo Real'!C128 -> 6365.261 | D128: =+REAL_Venta!D128+'Costo Real'!D128 -> 5909.1154 | E128: =+REAL_Venta!E128+'Costo Real'!E128 -> 6018.8488 | F128: =+REAL_Venta!F128+'Costo Real'!F128 -> 8570.0908 | G128: =+REAL_Venta!G128+'Costo Real'!G128 -> 7262.3533 | H128: =+REAL_Venta!H128+'Costo Real'!H128 -> 5728.3639 | I128: =+REAL_Venta!I128+'Costo Real'!I128 -> 3667.2595 | J128: =+REAL_Venta!J128+'Costo Real'!J128 -> 3874.6958 | Z128: B010 | AA128: Bamers | AB128: B010
A129: B011-Bamers Plaza Tobalaba | B129: =+REAL_Venta!B129+'Costo Real'!B129 -> 11370.791 | C129: =+REAL_Venta!C129+'Costo Real'!C129 -> 6946.8524 | D129: =+REAL_Venta!D129+'Costo Real'!D129 -> 7310.6097 | E129: =+REAL_Venta!E129+'Costo Real'!E129 -> 8443.0965 | F129: =+REAL_Venta!F129+'Costo Real'!F129 -> 16665.452 | G129: =+REAL_Venta!G129+'Costo Real'!G129 -> 10000.113 | H129: =+REAL_Venta!H129+'Costo Real'!H129 -> 5539.4961 | I129: =+REAL_Venta!I129+'Costo Real'!I129 -> 4536.5048 | J129: =+REAL_Venta!J129+'Costo Real'!J129 -> 5213.4562 | Z129: B011 | AA129: Bamers | AB129: B011
A130: B012-Bamers Mall Center Concep | B130: =+REAL_Venta!B130+'Costo Real'!B130 -> 10201.162 | C130: =+REAL_Venta!C130+'Costo Real'!C130 -> 4939.4311 | D130: =+REAL_Venta!D130+'Costo Real'!D130 -> 4913.7693 | E130: =+REAL_Venta!E130+'Costo Real'!E130 -> 6688.0029 | F130: =+REAL_Venta!F130+'Costo Real'!F130 -> 12001.946 | G130: =+REAL_Venta!G130+'Costo Real'!G130 -> 4870.6544 | H130: =+REAL_Venta!H130+'Costo Real'!H130 -> 5151.0585 | I130: =+REAL_Venta!I130+'Costo Real'!I130 -> 3930.3985 | J130: =+REAL_Venta!J130+'Costo Real'!J130 -> 3561.8383 | Z130: B012 | AA130: Bamers | AB130: B012
A131: B016-Bamers Alto Las Condes | B131: =+REAL_Venta!B131+'Costo Real'!B131 -> 25787.81 | C131: =+REAL_Venta!C131+'Costo Real'!C131 -> 11816.775 | D131: =+REAL_Venta!D131+'Costo Real'!D131 -> 11895.685 | E131: =+REAL_Venta!E131+'Costo Real'!E131 -> 16577.437 | F131: =+REAL_Venta!F131+'Costo Real'!F131 -> 27396.975 | G131: =+REAL_Venta!G131+'Costo Real'!G131 -> 16896.039 | H131: =+REAL_Venta!H131+'Costo Real'!H131 -> 452.76591 | I131: =+REAL_Venta!I131+'Costo Real'!I131 -> 0 | J131: =+REAL_Venta!J131+'Costo Real'!J131 -> 0 | Z131: B016 | AA131: Bamers | AB131: B016
A132: B019-Bamers Portal La Reina | B132: =+REAL_Venta!B132+'Costo Real'!B132 -> 12993.786 | C132: =+REAL_Venta!C132+'Costo Real'!C132 -> 6972.2108 | D132: =+REAL_Venta!D132+'Costo Real'!D132 -> 7056.2972 | E132: =+REAL_Venta!E132+'Costo Real'!E132 -> 8886.4743 | F132: =+REAL_Venta!F132+'Costo Real'!F132 -> 14848.93 | G132: =+REAL_Venta!G132+'Costo Real'!G132 -> 9291.7197 | H132: =+REAL_Venta!H132+'Costo Real'!H132 -> 7074.2876 | I132: =+REAL_Venta!I132+'Costo Real'!I132 -> 5318.5832 | J132: =+REAL_Venta!J132+'Costo Real'!J132 -> 7925.3067 | Z132: B019 | AA132: Bamers | AB132: B019
A133: B022-Bamers Plaza Egaña | B133: =+REAL_Venta!B133+'Costo Real'!B133 -> 10279.569 | C133: =+REAL_Venta!C133+'Costo Real'!C133 -> 7350.7585 | D133: =+REAL_Venta!D133+'Costo Real'!D133 -> 5958.3303 | E133: =+REAL_Venta!E133+'Costo Real'!E133 -> 7871.4986 | F133: =+REAL_Venta!F133+'Costo Real'!F133 -> 15502.794 | G133: =+REAL_Venta!G133+'Costo Real'!G133 -> 8917.5585 | H133: =+REAL_Venta!H133+'Costo Real'!H133 -> 5376.3757 | I133: =+REAL_Venta!I133+'Costo Real'!I133 -> 4556.8959 | J133: =+REAL_Venta!J133+'Costo Real'!J133 -> 6672.1503 | Z133: B022 | AA133: Bamers | AB133: B022
A134: B024-Bamers Plaza Oeste | B134: =+REAL_Venta!B134+'Costo Real'!B134 -> 13113.033 | C134: =+REAL_Venta!C134+'Costo Real'!C134 -> 8124.6809 | D134: =+REAL_Venta!D134+'Costo Real'!D134 -> 7162.4778 | E134: =+REAL_Venta!E134+'Costo Real'!E134 -> 10785.159 | F134: =+REAL_Venta!F134+'Costo Real'!F134 -> 23432.896 | G134: =+REAL_Venta!G134+'Costo Real'!G134 -> 11618.172 | H134: =+REAL_Venta!H134+'Costo Real'!H134 -> 7571.2675 | I134: =+REAL_Venta!I134+'Costo Real'!I134 -> 5189.6293 | J134: =+REAL_Venta!J134+'Costo Real'!J134 -> 6744.8598 | Z134: B024 | AA134: Bamers | AB134: B024
... A158: B023-Bamers Florida Center | B158: =+REAL_Venta!B158+'Costo Real'!B158 -> 10164.617 | C158: =+REAL_Venta!C158+'Costo Real'!C158 -> 872.81189 | D158: =+REAL_Venta!D158+'Costo Real'!D158 -> 0 | E158: =+REAL_Venta!E158+'Costo Real'!E158 -> 0 | F158: =+REAL_Venta!F158+'Costo Real'!F158 -> 0 | G158: =+REAL_Venta!G158+'Costo Real'!G158 -> 0 | H158: =+REAL_Venta!H158+'Costo Real'!H158 -> 0 | I158: =+REAL_Venta!I158+'Costo Real'!I158 -> 0 | J158: =+REAL_Venta!J158+'Costo Real'!J158 -> 0 | Z158: B023 | AA158: Bamers | AB158: B023
A159: B023-Bamers Florida Center | B159: =+REAL_Venta!B159+'Costo Real'!B159 -> 0 | C159: =+REAL_Venta!C159+'Costo Real'!C159 -> 0 | D159: =+REAL_Venta!D159+'Costo Real'!D159 -> 0 | E159: =+REAL_Venta!E159+'Costo Real'!E159 -> 0 | F159: =+REAL_Venta!F159+'Costo Real'!F159 -> 0 | G159: =+REAL_Venta!G159+'Costo Real'!G159 -> 0 | H159: =+REAL_Venta!H159+'Costo Real'!H159 -> 0 | I159: =+REAL_Venta!I159+'Costo Real'!I159 -> 0 | J159: =+REAL_Venta!J159+'Costo Real'!J159 -> 0 | AA159: Bamers
A160: 2001-Bold Plaza Vespucio | B160: =+REAL_Venta!B160+'Costo Real'!B160 -> 42754.784 | C160: =+REAL_Venta!C160+'Costo Real'!C160 -> 67140.946 | D160: =+REAL_Venta!D160+'Costo Real'!D160 -> 64501.663 | E160: =+REAL_Venta!E160+'Costo Real'!E160 -> 48639.644 | F160: =+REAL_Venta!F160+'Costo Real'!F160 -> 53226.767 | G160: =+REAL_Venta!G160+'Costo Real'!G160 -> 44633.782 | H160: =+REAL_Venta!H160+'Costo Real'!H160 -> 39810.365 | I160: =+REAL_Venta!I160+'Costo Real'!I160 -> 27219.656 | J160: =+REAL_Venta!J160+'Costo Real'!J160 -> 0 | AA160: Bamers
A161: 1011-Belsport Puerto Montt | B161: =+REAL_Venta!B161+'Costo Real'!B161 -> 50875.279 | C161: =+REAL_Venta!C161+'Costo Real'!C161 -> 73963.925 | D161: =+REAL_Venta!D161+'Costo Real'!D161 -> 56686.263 | E161: =+REAL_Venta!E161+'Costo Real'!E161 -> 40472.12 | F161: =+REAL_Venta!F161+'Costo Real'!F161 -> 35615.852 | G161: =+REAL_Venta!G161+'Costo Real'!G161 -> 25955.545 | H161: =+REAL_Venta!H161+'Costo Real'!H161 -> 26843.455 | I161: =+REAL_Venta!I161+'Costo Real'!I161 -> 30292.774 | J161: =+REAL_Venta!J161+'Costo Real'!J161 -> 28568.645 | Z161: B006 | AA161: Bamers | AB161: B006
A162: 5002-Drops MUT | B162: =+REAL_Venta!B162+'Costo Real'!B162 -> 0 | C162: =+REAL_Venta!C162+'Costo Real'!C162 -> 0 | D162: =+REAL_Venta!D162+'Costo Real'!D162 -> 0 | E162: =+REAL_Venta!E162+'Costo Real'!E162 -> 0 | F162: =+REAL_Venta!F162+'Costo Real'!F162 -> 0 | G162: =+REAL_Venta!G162+'Costo Real'!G162 -> 0 | H162: =+REAL_Venta!H162+'Costo Real'!H162 -> 0 | I162: =+REAL_Venta!I162+'Costo Real'!I162 -> 0 | J162: =+REAL_Venta!J162+'Costo Real'!J162 -> 0 | Z162: 2001 | AA162: Bold | AB162: 2001
A163: 2037-Bold Vespucio III | B163: =+REAL_Venta!B163+'Costo Real'!B163 -> 0 | C163: =+REAL_Venta!C163+'Costo Real'!C163 -> 0 | D163: =+REAL_Venta!D163+'Costo Real'!D163 -> 0 | E163: =+REAL_Venta!E163+'Costo Real'!E163 -> 0 | F163: =+REAL_Venta!F163+'Costo Real'!F163 -> 0 | G163: =+REAL_Venta!G163+'Costo Real'!G163 -> 0 | H163: =+REAL_Venta!H163+'Costo Real'!H163 -> 0 | I163: =+REAL_Venta!I163+'Costo Real'!I163 -> 94294.873 | J163: =+REAL_Venta!J163+'Costo Real'!J163 -> 199426.95 | Z163: 1011 | AA163: Belsport | AB163: 1011
A164: 7502-Hoka Marina | B164: =+REAL_Venta!B164+'Costo Real'!B164 -> 0 | C164: =+REAL_Venta!C164+'Costo Real'!C164 -> 0 | D164: =+REAL_Venta!D164+'Costo Real'!D164 -> 0 | E164: =+REAL_Venta!E164+'Costo Real'!E164 -> 0 | F164: =+REAL_Venta!F164+'Costo Real'!F164 -> 0 | G164: =+REAL_Venta!G164+'Costo Real'!G164 -> 0 | H164: =+REAL_Venta!H164+'Costo Real'!H164 -> 0 | I164: =+REAL_Venta!I164+'Costo Real'!I164 -> 0 | J164: =+REAL_Venta!J164+'Costo Real'!J164 -> 0 | AA164: Drops
A165: Bamers X | B165: =+REAL_Venta!B165+'Costo Real'!B165 -> 0 | C165: =+REAL_Venta!C165+'Costo Real'!C165 -> 0 | D165: =+REAL_Venta!D165+'Costo Real'!D165 -> 0 | E165: =+REAL_Venta!E165+'Costo Real'!E165 -> 0 | F165: =+REAL_Venta!F165+'Costo Real'!F165 -> 0 | G165: =+REAL_Venta!G165+'Costo Real'!G165 -> 0 | H165: =+REAL_Venta!H165+'Costo Real'!H165 -> 0 | I165: =+REAL_Venta!I165+'Costo Real'!I165 -> 0 | J165: =+REAL_Venta!J165+'Costo Real'!J165 -> 0 | AA165: Aufbau
A166: Bamers Y | B166: =+REAL_Venta!B166+'Costo Real'!B166 -> 0 | C166: =+REAL_Venta!C166+'Costo Real'!C166 -> 0 | D166: =+REAL_Venta!D166+'Costo Real'!D166 -> 0 | E166: =+REAL_Venta!E166+'Costo Real'!E166 -> 0 | F166: =+REAL_Venta!F166+'Costo Real'!F166 -> 0 | G166: =+REAL_Venta!G166+'Costo Real'!G166 -> 0 | H166: =+REAL_Venta!H166+'Costo Real'!H166 -> 0 | I166: =+REAL_Venta!I166+'Costo Real'!I166 -> 0 | J166: =+REAL_Venta!J166+'Costo Real'!J166 -> 0 | Z166: 2037 | AA166: Bold | AB166: 2037
A167: Apple Puerto Varas | B167: =+REAL_Venta!B167+'Costo Real'!B167 -> 0 | C167: =+REAL_Venta!C167+'Costo Real'!C167 -> 0 | D167: =+REAL_Venta!D167+'Costo Real'!D167 -> 0 | E167: =+REAL_Venta!E167+'Costo Real'!E167 -> 0 | F167: =+REAL_Venta!F167+'Costo Real'!F167 -> 0 | G167: =+REAL_Venta!G167+'Costo Real'!G167 -> 0 | H167: =+REAL_Venta!H167+'Costo Real'!H167 -> 0 | I167: =+REAL_Venta!I167+'Costo Real'!I167 -> 0 | J167: =+REAL_Venta!J167+'Costo Real'!J167 -> 0 | Z167: 7502 | AA167: Hoka | AB167: #N/A
A168: Hoka Parque Arauco | B168: =+REAL_Venta!B168+'Costo Real'!B168 -> 0 | C168: =+REAL_Venta!C168+'Costo Real'!C168 -> 0 | D168: =+REAL_Venta!D168+'Costo Real'!D168 -> 0 | E168: =+REAL_Venta!E168+'Costo Real'!E168 -> 0 | F168: =+REAL_Venta!F168+'Costo Real'!F168 -> 0 | G168: =+REAL_Venta!G168+'Costo Real'!G168 -> 0 | H168: =+REAL_Venta!H168+'Costo Real'!H168 -> 0 | I168: =+REAL_Venta!I168+'Costo Real'!I168 -> 0 | J168: =+REAL_Venta!J168+'Costo Real'!J168 -> 0 | Z168: 7503 | AA168: Hoka | AB168: #N/A
A169: Drops Parque Arauco | B169: =+REAL_Venta!B169+'Costo Real'!B169 -> 0 | C169: =+REAL_Venta!C169+'Costo Real'!C169 -> 0 | D169: =+REAL_Venta!D169+'Costo Real'!D169 -> 0 | E169: =+REAL_Venta!E169+'Costo Real'!E169 -> 0 | F169: =+REAL_Venta!F169+'Costo Real'!F169 -> 0 | G169: =+REAL_Venta!G169+'Costo Real'!G169 -> 0 | H169: =+REAL_Venta!H169+'Costo Real'!H169 -> 0 | I169: =+REAL_Venta!I169+'Costo Real'!I169 -> 0 | J169: =+REAL_Venta!J169+'Costo Real'!J169 -> 0 | Z169: 5003 | AA169: Drops | AB169: #N/A
A172: BELSPORT | B172: 2951289.8 | C172: 4323556.6 | D172: 3951355 | E172: 2630802.4 | F172: 2856254.1 | G172: 2255814.7 | H172: 2742788.6 | I172: 2897701.3 | J172: 3647331.3
...

Sheet REAL_Venta
A1: Sucursal | B1: 45658 | C1: 45689 | D1: 45717 | E1: 45748 | F1: 45778 | G1: 45809 | H1: 45839 | I1: 45870 | J1: 45901 | K1: 45931 | L1: 45962 | M1: 45992 | N1: 46023 | O1: 46054 | P1: 46082 | Q1: 46113 | R1: 46143 | S1: 46174 | T1: 46204 | U1: 46235 | V1: 46266 | W1: 46296 | X1: 46327 | Y1: 46357
A2: 1000-Belsport Ahumada | B2: 94442.07 | C2: 136362.69 | D2: 139768.74 | E2: 95486.522 | F2: 105271.44 | G2: 78101.871 | H2: 108664.61 | I2: 102650.09 | J2: 122111.78
A3: 1001-Belsport Puente | B3: 48680.739 | C3: 76167.103 | D3: 85069.55 | E3: 58263.898 | F3: 66261.899 | G3: 48063.822 | H3: 56535.35 | I3: 56749.682 | J3: 70936.295
A4: 1003-Belsport Maipu | B4: 79869.143 | C4: 147193.23 | D4: 148639.5 | E4: 100352.13 | F4: 102286.96 | G4: 77215.229 | H4: 88413.897 | I4: 114356.11 | J4: 125822.06
A5: 1004-Belsport Rosas | B5: 100237.77 | C5: 151962.43 | D5: 154154.95 | E5: 117878.77 | F5: 125511.1 | G5: 84508.477 | H5: 108117.58 | I5: 123005.02 | J5: 139148.28
A6: 1005-Belsport San Bernardo | B6: 65305.815 | C6: 125720.03 | D6: 135709.78 | E6: 90281.96 | F6: 102702.85 | G6: 80998.253 | H6: 91628.692 | I6: 108073.46 | J6: 139916.25
A7: 1006-Belsport Vespucio I | B7: 79185.974 | C7: 146226.03 | D7: 140505.04 | E7: 91171.661 | F7: 111671.72 | G7: 84377.261 | H7: 94399.589 | I7: 115127.31 | J7: 155124.41
A8: 1007-Belsport Rancagua | B8: 75511.862 | C8: 134747.78 | D8: 110500.31 | E8: 71115.432 | F8: 78664.538 | G8: 54571.954 | H8: 70448.297 | I8: 86758.629 | J8: 110952.19
A9: 1008-Belsport Marina | B9: 150318.24 | C9: 155322.56 | D9: 134521.9 | E9: 92913.651 | F9: 83074.281 | G9: 55933.627 | H9: 68307.418 | I9: 80331.68 | J9: 94182.308
A10: 1009-Belsport Calama | B10: 79268.409 | C10: 110059.63 | D10: 119613.73 | E10: 91163.473 | F10: 98694.882 | G10: 73855.518 | H10: 82629.816 | I10: 90891.418 | J10: 85005.097
A11: 1010-Belsport Concepcion I | B11: 120375.69 | C11: 181097.1 | D11: 148612.97 | E11: 102899.02 | F11: 111171.35 | G11: 76997.146 | H11: 87954.055 | I11: 107080.62 | J11: 130272.36
A12: 1012-Belsport Plaza Oeste II | B12: 53064.184 | C12: 100182.87 | D12: 96872.333 | E12: 66330.294 | F12: 73448.706 | G12: 46239.451 | H12: 57143.346 | I12: 70954.815 | J12: 86863.429
A13: 1013-Belsport Los Angeles | B13: 81224.837 | C13: 140001.52 | D13: 124258.18 | E13: 82938.5 | F13: 84099.865 | G13: 53979.126 | H13: 75437.598 | I13: 89092.392 | J13: 107298.77
... A169: P-Drops Parque Arauco | B169: 0 | C169: 0 | D169: 0 | E169: 0 | F169: 0 | G169: 0 | H169: 0 | I169: 0 | J169: 0

Sheet REAL_Contribución
A1: Sucursal | B1: 45658 | C1: 45689 | D1: 45717 | E1: 45748 | F1: 45778 | G1: 45809 | H1: 45839 | I1: 45870 | J1: 45901 | K1: 45931 | L1: 45962 | M1: 45992 | N1: 46023 | O1: 46054 | P1: 46082 | Q1: 46113 | R1: 46143 | S1: 46174 | T1: 46204 | U1: 46235 | V1: 46266 | W1: 46296 | X1: 46327 | Y1: 46357
A2: 1000-Belsport Ahumada | B2: =+IFERROR('Contri Real'!B2/REAL_Venta!B2,0) -> 0.41192036 | C2: =+IFERROR('Contri Real'!C2/REAL_Venta!C2,0) -> 0.42980948 | D2: =+IFERROR('Contri Real'!D2/REAL_Venta!D2,0) -> 0.43824234 | E2: =+IFERROR('Contri Real'!E2/REAL_Venta!E2,0) -> 0.43891815 | F2: =+IFERROR('Contri Real'!F2/REAL_Venta!F2,0) -> 0.38293805 | G2: =+IFERROR('Contri Real'!G2/REAL_Venta!G2,0) -> 0.34922104 | H2: =+IFERROR('Contri Real'!H2/REAL_Venta!H2,0) -> 0.3326602 | I2: =+IFERROR('Contri Real'!I2/REAL_Venta!I2,0) -> 0.40276536 | J2: =+IFERROR('Contri Real'!J2/REAL_Venta!J2,0) -> 0.32256096
A3: 1001-Belsport Puente | B3: =+IFERROR('Contri Real'!B3/REAL_Venta!B3,0) -> 0.40040865 | C3: =+IFERROR('Contri Real'!C3/REAL_Venta!C3,0) -> 0.43182614 | D3: =+IFERROR('Contri Real'!D3/REAL_Venta!D3,0) -> 0.43490259 | E3: =+IFERROR('Contri Real'!E3/REAL_Venta!E3,0) -> 0.42403369 | F3: =+IFERROR('Contri Real'!F3/REAL_Venta!F3,0) -> 0.38714773 | G3: =+IFERROR('Contri Real'!G3/REAL_Venta!G3,0) -> 0.35332239 | H3: =+IFERROR('Contri Real'!H3/REAL_Venta!H3,0) -> 0.31328288 | I3: =+IFERROR('Contri Real'!I3/REAL_Venta!I3,0) -> 0.35757949 | J3: =+IFERROR('Contri Real'!J3/REAL_Venta!J3,0) -> 0.33926261
A4: 1003-Belsport Maipu | B4: =+IFERROR('Contri Real'!B4/REAL_Venta!B4,0) -> 0.42916752 | C4: =+IFERROR('Contri Real'!C4/REAL_Venta!C4,0) -> 0.44502305 | D4: =+IFERROR('Contri Real'!D4/REAL_Venta!D4,0) -> 0.44115243 | E4: =+IFERROR('Contri Real'!E4/REAL_Venta!E4,0) -> 0.43539427 | F4: =+IFERROR('Contri Real'!F4/REAL_Venta!F4,0) -> 0.42123429 | G4: =+IFERROR('Contri Real'!G4/REAL_Venta!G4,0) -> 0.38121954 | H4: =+IFERROR('Contri Real'!H4/REAL_Venta!H4,0) -> 0.37855662 | I4: =+IFERROR('Contri Real'!I4/REAL_Venta!I4,0) -> 0.41935237 | J4: =+IFERROR('Contri Real'!J4/REAL_Venta!J4,0) -> 0.38067866
A5: 1004-Belsport Rosas | B5: =+IFERROR('Contri Real'!B5/REAL_Venta!B5,0) -> 0.41176267 | C5: =+IFERROR('Contri Real'!C5/REAL_Venta!C5,0) -> 0.4364253 | D5: =+IFERROR('Contri Real'!D5/REAL_Venta!D5,0) -> 0.43967669 | E5: =+IFERROR('Contri Real'!E5/REAL_Venta!E5,0) -> 0.43086536 | F5: =+IFERROR('Contri Real'!F5/REAL_Venta!F5,0) -> 0.38733588 | G5: =+IFERROR('Contri Real'!G5/REAL_Venta!G5,0) -> 0.39061138 | H5: =+IFERROR('Contri Real'!H5/REAL_Venta!H5,0) -> 0.36062474 | I5: =+IFERROR('Contri Real'!I5/REAL_Venta!I5,0) -> 0.41879199 | J5: =+IFERROR('Contri Real'!J5/REAL_Venta!J5,0) -> 0.38119929
A6: 1005-Belsport San Bernardo | B6: =+IFERROR('Contri Real'!B6/REAL_Venta!B6,0) -> 0.38562563 | C6: =+IFERROR('Contri Real'!C6/REAL_Venta!C6,0) -> 0.41702822 | D6: =+IFERROR('Contri Real'!D6/REAL_Venta!D6,0) -> 0.42929919 | E6: =+IFERROR('Contri Real'!E6/REAL_Venta!E6,0) -> 0.41969137 | F6: =+IFERROR('Contri Real'!F6/REAL_Venta!F6,0) -> 0.39351917 | G6: =+IFERROR('Contri Real'!G6/REAL_Venta!G6,0) -> 0.37546935 | H6: =+IFERROR('Contri Real'!H6/REAL_Venta!H6,0) -> 0.35920935 | I6: =+IFERROR('Contri Real'!I6/REAL_Venta!I6,0) -> 0.40719529 | J6: =+IFERROR('Contri Real'!J6/REAL_Venta!J6,0) -> 0.37000534
A7: 1006-Belsport Vespucio I | B7: =+IFERROR('Contri Real'!B7/REAL_Venta!B7,0) -> 0.42183302 | C7: =+IFERROR('Contri Real'!C7/REAL_Venta!C7,0) -> 0.44035572 | D7: =+IFERROR('Contri Real'!D7/REAL_Venta!D7,0) -> 0.44707436 | E7: =+IFERROR('Contri Real'!E7/REAL_Venta!E7,0) -> 0.44616867 | F7: =+IFERROR('Contri Real'!F7/REAL_Venta!F7,0) -> 0.41852344 | G7: =+IFERROR('Contri Real'!G7/REAL_Venta!G7,0) -> 0.40644077 | H7: =+IFERROR('Contri Real'!H7/REAL_Venta!H7,0) -> 0.38943671 | I7: =+IFERROR('Contri Real'!I7/REAL_Venta!I7,0) -> 0.42714401 | J7: =+IFERROR('Contri Real'!J7/REAL_Venta!J7,0) -> 0.37841294
A8: 1007-Belsport Rancagua | B8: =+IFERROR('Contri Real'!B8/REAL_Venta!B8,0) -> 0.41625423 | C8: =+IFERROR('Contri Real'!C8/REAL_Venta!C8,0) -> 0.42685985 | D8: =+IFERROR('Contri Real'!D8/REAL_Venta!D8,0) -> 0.43818369 | E8: =+IFERROR('Contri Real'!E8/REAL_Venta!E8,0) -> 0.44125532 | F8: =+IFERROR('Contri Real'!F8/REAL_Venta!F8,0) -> 0.42725691 | G8: =+IFERROR('Contri Real'!G8/REAL_Venta!G8,0) -> 0.42359578 | H8: =+IFERROR('Contri Real'!H8/REAL_Venta!H8,0) -> 0.36722806 | I8: =+IFERROR('Contri Real'!I8/REAL_Venta!I8,0) -> 0.42343216 | J8: =+IFERROR('Contri Real'!J8/REAL_Venta!J8,0) -> 0.36422373
A9: 1008-Belsport Marina | B9: =+IFERROR('Contri Real'!B9/REAL_Venta!B9,0) -> 0.41337939 | C9: =+IFERROR('Contri Real'!C9/REAL_Venta!C9,0) -> 0.44060001 | D9: =+IFERROR('Contri Real'!D9/REAL_Venta!D9,0) -> 0.44344243 | E9: =+IFERROR('Contri Real'!E9/REAL_Venta!E9,0) -> 0.42757527 | F9: =+IFERROR('Contri Real'!F9/REAL_Venta!F9,0) -> 0.39076871 | G9: =+IFERROR('Contri Real'!G9/REAL_Venta!G9,0) -> 0.3585399 | H9: =+IFERROR('Contri Real'!H9/REAL_Venta!H9,0) -> 0.39507903 | I9: =+IFERROR('Contri Real'!I9/REAL_Venta!I9,0) -> 0.4238485 | J9: =+IFERROR('Contri Real'!J9/REAL_Venta!J9,0) -> 0.35165271
A10: 1009-Belsport Calama | B10: =+IFERROR('Contri Real'!B10/REAL_Venta!B10,0) -> 0.41908754 | C10: =+IFERROR('Contri Real'!C10/REAL_Venta!C10,0) -> 0.43085132 | D10: =+IFERROR('Contri Real'!D10/REAL_Venta!D10,0) -> 0.4291144 | E10: =+IFERROR('Contri Real'!E10/REAL_Venta!E10,0) -> 0.42815136 | F10: =+IFERROR('Contri Real'!F10/REAL_Venta!F10,0) -> 0.41490867 | G10: =+IFERROR('Contri Real'!G10/REAL_Venta!G10,0) -> 0.37630976 | H10: =+IFERROR('Contri Real'!H10/REAL_Venta!H10,0) -> 0.38017333 | I10: =+IFERROR('Contri Real'!I10/REAL_Venta!I10,0) -> 0.40853479 | J10: =+IFERROR('Contri Real'!J10/REAL_Venta!J10,0) -> 0.3782575
A11: 1010-Belsport Concepcion I | B11: =+IFERROR('Contri Real'!B11/REAL_Venta!B11,0) -> 0.42285906 | C11: =+IFERROR('Contri Real'!C11/REAL_Venta!C11,0) -> 0.43803898 | D11: =+IFERROR('Contri Real'!D11/REAL_Venta!D11,0) -> 0.44318897 | E11: =+IFERROR('Contri Real'!E11/REAL_Venta!E11,0) -> 0.43833617 | F11: =+IFERROR('Contri Real'!F11/REAL_Venta!F11,0) -> 0.41438939 | G11: =+IFERROR('Contri Real'!G11/REAL_Venta!G11,0) -> 0.39998573 | H11: =+IFERROR('Contri Real'!H11/REAL_Venta!H11,0) -> 0.35633411 | I11: =+IFERROR('Contri Real'!I11/REAL_Venta!I11,0) -> 0.41143284 | J11: =+IFERROR('Contri Real'!J11/REAL_Venta!J11,0) -> 0.33682089
A12: 1012-Belsport Plaza Oeste II | B12: =+IFERROR('Contri Real'!B12/REAL_Venta!B12,0) -> 0.41633187 | C12: =+IFERROR('Contri Real'!C12/REAL_Venta!C12,0) -> 0.43921417 | D12: =+IFERROR('Contri Real'!D12/REAL_Venta!D12,0) -> 0.43000174 | E12: =+IFERROR('Contri Real'!E12/REAL_Venta!E12,0) -> 0.43836983 | F12: =+IFERROR('Contri Real'!F12/REAL_Venta!F12,0) -> 0.40936039 | G12: =+IFERROR('Contri Real'!G12/REAL_Venta!G12,0) -> 0.36097574 | H12: =+IFERROR('Contri Real'!H12/REAL_Venta!H12,0) -> 0.36492356 | I12: =+IFERROR('Contri Real'!I12/REAL_Venta!I12,0) -> 0.39692697 | J12: =+IFERROR('Contri Real'!J12/REAL_Venta!J12,0) -> 0.36888509
A13: 1013-Belsport Los Angeles | B13: =+IFERROR('Contri Real'!B13/REAL_Venta!B13,0) -> 0.41509733 | C13: =+IFERROR('Contri Real'!C13/REAL_Venta!C13,0) -> 0.4310174 | D13: =+IFERROR('Contri Real'!D13/REAL_Venta!D13,0) -> 0.43552429 | E13: =+IFERROR('Contri Real'!E13/REAL_Venta!E13,0) -> 0.43978352 | F13: =+IFERROR('Contri Real'!F13/REAL_Venta!F13,0) -> 0.40434483 | G13: =+IFERROR('Contri Real'!G13/REAL_Venta!G13,0) -> 0.40312021 | H13: =+IFERROR('Contri Real'!H13/REAL_Venta!H13,0) -> 0.35846222 | I13: =+IFERROR('Contri Real'!I13/REAL_Venta!I13,0) -> 0.41174403 | J13: =+IFERROR('Contri Real'!J13/REAL_Venta!J13,0) -> 0.34678287
